---
title: 化学品预测毒理学平台后台搭建笔记
date: 2019-06-06
tags:
- 环境搭建
- Django
categories: 
- 调试记录
---

# 2019-07-01

## 过程记录

嗨~早上好呀！不知道今天你忙不忙哈哈。我来汇报一下这几天的工作，总共分为两点，有一点需要你抉择，另一点需要你来审核一下。
第一点：我上周五晚上测试了新的chemwriter,但是可能是没有找到正确的配置方法，导致画图框架上面的按钮图标无法加载出来。由于我之前没怎么学过前端关于css和js的知识，所以要搞定这个框架的自动加载问题可能要很长一段时间，我目前的想法是先将现有的代码部署到那天扛回来的台式机上，然后上线之后再慢慢调试这个画图框架的加载问题，请问这样可以嘛？
第二点：然后之前你不是说要把项目记录一下嘛。我这几天找到了一个感觉很好用的项目记录软件--trello.我这两天在上面简单做了一个看板，之后重建的cptp平台的工作都会按照顺序记录在这个看板上，希望可以方便进度汇报和以后的查看。但是需要你用邮箱注册一个trello的账号，然后我把你拉进看板里，这样你能更系统地看到我重建cptp的工作啦，而且如果遇到问题可以通过卡片的方式在trello进行讨论，方便以后整理。同时，我会将以前遇到的问题逐步整理到看板中，这样以后出现同样的问题可以用来做参考。
嗯，今天的工作汇报主要是这些~
祝生活愉快(*^▽^*)。
emmm 写了这么多我打算发邮件了2333.
2019年7月1日
姜东

# 2019-06-18

## problem_061801_unsolved 

### 问题描述

在用户点击账号激活邮件里的激活链接的时候，runserver命令的后台会出现如下报错信息：

    Traceback (most recent call last):
    File "/usr/lib/python2.7/wsgiref/handlers.py", line 86, in run
        self.finish_response()
    File "/usr/lib/python2.7/wsgiref/handlers.py", line 128, in finish_response
        self.write(data)
    File "/usr/lib/python2.7/wsgiref/handlers.py", line 217, in write
        self._write(data)
    File "/usr/lib/python2.7/socket.py", line 328, in write
        self.flush()
    File "/usr/lib/python2.7/socket.py", line 307, in flush
        self._sock.sendall(view[write_offset:write_offset+buffer_size])
    error: [Errno 32] Broken pipe
    [18/Jun/2019 23:40:43] "GET /static/flat-ui/fonts/lato/lato-bold.woff HTTP/1.1" 500 59
    ----------------------------------------
    Exception happened during processing of request from ('10.9.16.128', 52341)
    Traceback (most recent call last):
    File "/usr/lib/python2.7/SocketServer.py", line 596, in process_request_thread
        self.finish_request(request, client_address)
    File "/usr/lib/python2.7/SocketServer.py", line 331, in finish_request
        self.RequestHandlerClass(request, client_address, self)
    File "/home/jiangdong/.virtualenvs/ctws/local/lib/python2.7/site-packages/django/core/servers/basehttp.py", line 126, in __init__
        super(WSGIRequestHandler, self).__init__(*args, **kwargs)
    File "/usr/lib/python2.7/SocketServer.py", line 654, in __init__
        self.finish()
    File "/usr/lib/python2.7/SocketServer.py", line 713, in finish
        self.wfile.close()
    File "/usr/lib/python2.7/socket.py", line 283, in close
        self.flush()
    File "/usr/lib/python2.7/socket.py", line 307, in flush
        self._sock.sendall(view[write_offset:write_offset+buffer_size])
    error: [Errno 32] Broken pipe

### 执行测试
在active函数中进行了日志的输出，发现输出正常，无报错信息，但是依旧无法登录新用户。打算下一步
测试更深层次的函数。

    [19/Jun/2019 00:39:12] "GET /accounts/register/complete/ HTTP/1.1" 200 4037
    active begin!
    ac key is:29714c0432eac0e00114b4a71d163597aa7ddb50
    accout get!
    active over!
    [19/Jun/2019 00:44:20] "GET /accounts/active/29714c0432eac0e00114b4a71d163597aa7ddb50/ HTTP/1.1" 200 4019

### 解决方法(2019-06-28更新)

原因是系统时间不对，导致后台误认为激活邮件已经过期，更改系统时间相关代码即可。

文件：utils/__init__.py

    def get_real_now():
        #hack, only for mopac2012.exe expired
        # d = datetime.datetime.now() + datetime.timedelta(days=730)
        # modified by dong on 2019-6-20
        # Reasons:at pervious code, mopac2012 may need the system time to be in its active time, 
        # but now we use new mopac,so we need not to put a timdelta here
        d = datetime.datetime.now() 
        s = time.mktime(d.timetuple())
        now = datetime.datetime.fromtimestamp(s)
        chemistry_logger.info('------nws get real now %s' % now)
        return now 
(2019-06-28更新结束)

# 2019-06-14

Emm 今天效率略微低下

主要是阅读了用户注册部分的代码：

大致步骤为：注册->激活->登陆->登出

测试发现注册发送注册邮件功能是正常的，登陆登出功能也是正常的。如果直接在后台更改用户的active权限，新的用户也是可以登陆的。

主要问题是出现在用户激活的部分。这部分代码集中在Users/views.py的active函数以及users/models.py的RegistrationManager类和RegistrationProfile类 

下一步打算设计一个测试情况，并在原代码中加入输出语句，详细定位出错位置。

# 2019-06-13

好了！

Mopac找不到的原因是没有建立软连接至系统可执行文件的搜索目录，原先的方式是通过命令别名的形式调用的，建立之后就可以运行了,即解决了问题 [problem_061201](#problem_061201_solved)

计算任务可以成功！
报告发送失败是因为邮箱的smtp服务没有开启，更换之后就可以了！
现在可以发送报告！

目前主要问题就剩下新用户没法验证登录，画图插件更新以及计算功能测试了！

# 2019-06-12

## problem_061201_solved

### 描述：

最近编译并配置好了openbabel,能够正常运行，但是提交计算任务有出现了新的问题，提示找不到mopac

### 错误日志：

celeryd 后台输出含有如下信息：

    /bin/sh: 1: mopac: not found

### 解决办法（2019-06-13更新）：

Mopac找不到的原因是没有建立软连接至系统可执行文件的搜索目录，原先的方式是通过命令别名的形式调用的，在/usr/bin目录下建立软链接之后就可以运行了

（2019-06-13更新结束）

# 2019-06-07

## 编译含有png输出支持的openbable


* 1.下载源码

    https://sourceforge.net/projects/openbabel/files/openbabel/2.4.1/openbabel-2.4.1.tar.gz/download

* 2.安装额外支持的包

    sudo apt install libboost-dev
    sudo apt-get install libcairo2-dev libxml2-dev zlib1g-dev libeigen2-dev libopenbabel-dev

* 3.安装对应版本编译器

     sudo apt-get install  g++-4.4 g++-4.4-multilib gcc-4.4 gcc-4.4-multilib

* 4.移除原先的openbabel

    sudo apt-get remove python-openbabel openbabel

* 4.解压源码

    tar -xzvf openbabel-2.3.1.tar.gz

* 5.进行编译命令

    cd openbabel-2.4.1/
    mkdir build
    mkdir -p ~/opt/openbabel-install
    cd build
    cmake .. -DCMAKE_INSTALL_PREFIX=~/opt/openbabel-install -DPYTHON_BINDINGS=ON -DBUILD_GUI=OFF

    cmake .. -DCMAKE_INSTALL_PREFIX=~/opt/openbabel-install -DPYTHON_BINDINGS=ON
在cmake中的CMAKE_CXX_FLAGS_RELEASE后面添加 --std=c++11
    CMAKE_CXX_FLAGS_RELEASE:STRING=-O3 -DNDEBUG -std=c++11

### issues:

* gcc g++ 版本不兼容 

https://blog.csdn.net/yile0000/article/details/80105625



# 2019-06-06

## 解决了[problem_060501](#problem_060501_solved)

## 找到后台数据库管理界面（新发现）

IP:port/admin

## problem_060601_unsolved

描述：

用户无法注册登录的问题

出错日志：

    Exception Type:	SMTPAuthenticationError
    Exception Value:	(535, 'Error: authentication failed')

原因分析：

邮件服务没有通过认证，无法正常激活。

## problem_060602_solved

描述：

openbabel问题不支持png图片生成

出错日志：

    [2019-06-06 00:10:20,183: ERROR/Worker-15] failed to submit task to prediction model
    Traceback (most recent call last):
    File "/home/jiangdong/workspace/CTWS/ChemToolsWebService/chemistry/tasks.py", line 101, in calculateTask
        generate_mol_image(task)
    File "/home/jiangdong/workspace/CTWS/ChemToolsWebService/chemistry/util.py", line 107, in generate_mol_image
        mol.draw(show=False, filename=ppath)
    File "/usr/lib/python2.7/dist-packages/pybel.py", line 502, in draw
        raise ImportError(errormessage)
    ImportError: PNG output format not found. You should compile Open Babel with PNG support. See installation instructions for more information.

解决方法(2019-06-18更新):
(编译含有png输出支持的openbable)[## 编译含有png输出支持的openbable]

详情请在本页搜索“编译含有png输出支持的openbable”或者点击链接
（2019-06-13更新结束）

## problem_060603_unsolved 

问题描述：

    UnboundLocalError: local variable 'suite' referenced before assignment(未解决)

出错日志：

    [2019-06-06 00:10:20,199: ERROR/MainProcess] Task chemistry.tasks.calculateTask[4898a17f-30b6-4ef7-a3f4-054b12dd719a] raised unexpected: UnboundLocalError("local variable 'suite' referenced before assignment",)
    Traceback (most recent call last):
    File "/home/jiangdong/.local/lib/python2.7/site-packages/celery/app/trace.py", line 240, in trace_task
        R = retval = fun(*args, **kwargs)
    File "/home/jiangdong/.local/lib/python2.7/site-packages/celery/app/trace.py", line 437, in __protected_call__
        return self.run(*args, **kwargs)
    File "/home/jiangdong/workspace/CTWS/ChemToolsWebService/chemistry/tasks.py", line 138, in calculateTask
        suite.status_id = StatusCategory.objects.get(category=STATUS_FAILED)
    UnboundLocalError: local variable 'suite' referenced before assignment


# 2019-06-05

## problem_060501_solved

django报错提示：

    OperationalError: (1054, "Unknown column 'local_search_id' in 'field list'")

出错日志：

    [2019-06-05 21:38:21,513: ERROR/Worker-15] failed to generate suite_task:1a8292d1-5820-4f01-8743-e131f889ecbd Traceback (most recent call last): File "/home/jiangdong/workspace/CTWS/ChemToolsWebService/chemistry/util.py", line 451, in generate_calculate_task handle_smile_task(smile, model, sid, local_search_id) File "/home/jiangdong/workspace/CTWS/ChemToolsWebService/chemistry/util.py", line 352, in handle_smile_task save_record(fpath, model, sid, ORIGIN_SMILE, smile, local_search_id) File "/home/jiangdong/workspace/CTWS/ChemToolsWebService/chemistry/util.py", line 261, in save_record processed_f.save()

原因分析：

发现任务提交出错发生在chemistry/util.py的save_record函数中

底层错误为：

    OperationalError: (1054, "Unknown column 'local_search_id' in 'field list'")

目前怀疑为数据库中缺少对应的项，正在根据代码核实涉及哪部分的数据库。

解决方法(2019-06-06更新)

进入数据库，运行

    alter table chemistry_processedfile add column local_search_id INT(11) NULL;
(2019-06-06更新结束)
# 2019-06-03

画图框架需要手动刷新显示，故在html的渲染文件中添加一行温馨提示，添加位置在templates/newtask.html中\{\% include&nbsp "widgets/chem-draw.html" \%\}之后。
添加内容为

    <font style=”vertical-align: inherit;”>若显示不正常右键绘图区域重新加载框架</font>

# 2019-06-02

任务列表界面无法访问，发现原因是生成的数据库中的对应表缺少一项，手动在数据库中添加即可。命令如下：

    mysql –uroot –p
    root
    use Chemistry;  
    alter table chemistry_suitetask add column is_hide TINYINT(1) NOT NULL DEFAULT 0;
    alter table chemistry_singletask add column is_hide TINYINT(1) NOT NULL DEFAULT 0;

{% asset_img 190602.jpg fig1 %}

# 2019-06-01

## 一些新的发现？

* tools目录下的generate_models.py会根据data文件夹下的csv文件生成chemistry/calcore/matrix/下的py文件。
* tools目录下的gen_check.py会根据data文件夹下的csv文件生成tools/data/check下的py文件。

* tools/deploy目录下的import_local.py文件好像是导入啥东西的 没有细究。。。
* tools/deploy目录下的build_production是用来配置生产环境相关目录的 主要是新建一些相关目录 以及安装对应的依赖包 和初始化数据库。

* 要安装supervisor

sudo pip2 install supervisor

* python manage.py collectstatic

# 2019-05-28

## redis安装及配置

[redis安装配置](https://www.cnblogs.com/GoQC/p/5764201.html)
[django redis配置](https://blog.csdn.net/m0_37886429/article/details/82556935)

apt-get install redis-server
# 2019-05-18

使用不同的settings
新建settings文件夹，将原先的settings.py配置成base.py,
root_dir向上加一层目录
copy dev.py至settings文件夹
如下形式启动

python2 manage.py runserver --settings=./settings.settings_dev.py


# 2019-05-15

## CPTP平台进展记录

{% asset_img 2019-05-15-1.jpg fig1 %}

图一

{% asset_img 2019-05-15-2.jpg fig1 %}

图二

### 进展说明

经过各种依赖库的安装及相关框架的配置，现在已能够在本地访问平台首页，相关测试结果如下：
* 首页、平台远景、软件帮助这三个页面的内容目前都是一样的…见图一。
* 图二是“预测计算-新建计算”的页面，但目前还不能提交计算原因可能是Dragon的license还没有配置上，等license配置结束应该就可以正常计算
* “预测计算-任务列表”页面访问会出错，估计原因有两种：一是没有预测任务，所以访问出错。二是网站本身链接不存在或者缺少三方包导致访问出错。
* 分子绘图界面目前显示有些问题，可能是先关文件在源仓库的缺失导致的，需要进一步分析解决。
* 文件上传功能需要后续继续测试。

### 接下来的工作

* 找一台在机房的节点重新部署平台。
* 等待官网发放license，继续测试计算功能。
* 阅读相关功能模块源码，找出进展3,4中问题的具体原因。
* 根据提供的资料，完善平台的首页，平台远景以及软件帮助的静态界面。


# 2019-05-10

今天的思路是采用虚拟环境virtualenv在16.04上使用python2.7配置环境。

* 添加32位库的支持

改为 sudo apt-get install g++-multilib 

# 2019-04-23

下载了bootstrap 目前还不知道有啥用

安装Django[官网链接](https://docs.djangoproject.com/zh-hans/2.2/topics/install/#installing-official-release)

更改了fail_n*n.png的文件名字，使得仓库能够被完整下载

更新了requirement文件,解决了python三方包的依赖问题
**但是没有测试三方包能否在现有代码中运行**

* 错误1

    * 描述：
    
        -bash: ./tools/build_env.sh: /bin/bash^M: bad interpreter: No such file or directory
    * 解决办法
        [链接](https://www.cnblogs.com/zyb-pp/p/6429448.html)

* 错误2
    
    * 描述：

        找不到virtualenv: command not found

    * 解决方法

        安装virtualenv
        pip3 install --user virtualenv

总结：现在这份仓库的代码使用的Django-1.6.3和python2的版本，可以说非常的古老，如果要方便后续开发，最好是能转成Django-2.2和python3.5不过这个工作量很多，因为Django2.x相比1.x版本是全新的一个版本，而且只能支持python3，需要慎重考虑。


